<HTML>
<HEAD>
<meta charset="UTF-8">
<title>A_Coroutines_Intro.J_underTheHood_3 - </title>
<link rel="stylesheet" href="../../style.css">
</HEAD>
<BODY>
<a href="../index.html">pl.mareklangiewicz.myblog.coroutines</a>&nbsp;/&nbsp;<a href="index.html">A_Coroutines_Intro</a>&nbsp;/&nbsp;<a href=".">J_underTheHood_3</a><br/>
<br/>
<h1>J_underTheHood_3</h1>
<a name="pl.mareklangiewicz.myblog.coroutines.A_Coroutines_Intro$J_underTheHood_3()"></a>
<code><span class="keyword">fun </span><span class="identifier">J_underTheHood_3</span><span class="symbol">(</span><span class="symbol">)</span><span class="symbol">: </span><span class="identifier">Unit</span></code>
<p>Under the hood - error case investigation
FIXME NOW: this example should never print "coroutine end", but it does immediately!</p>
<pre><code class="lang-kotlin">val mynever: suspend () -&gt; Unit = {
    suspendCoroutine&lt;Unit&gt; { continuation -&gt;
        "Got continuation: $continuation, but I will never call .resume(Unit)".p
    }
}
val coroutine: suspend () -&gt; Unit = {
    "coroutine start".p
    mynever()
    "coroutine end - THIS LINE SHOULD NEVER BE CALLED!".p
}
val completion = object : Continuation&lt;Unit&gt; {
    override val context = EmptyCoroutineContext
    override fun resume(value: Unit) {
        "completion: completed normally".p
    }
    override fun resumeWithException(exception: Throwable) {
        "completion: exception: $exception".p
    }
}
"main: start".p
val continuation = coroutine.createCoroutine(completion)
"main: after createCoroutine".p
continuation.resume(Unit)
"main: after continuation resume (to start coroutine)".p
Thread.sleep(3000)
"main: after sleep 3000".p</code></pre>
</BODY>
</HTML>
